<?xml version="1.0"?>
<robot name="mobile_base" xmlns:xacro="http://ros.org/wiki/xacro">
  <!--<xacro:macro name="IPS_convert" params="inches" />-->

  <xacro:property name="PI" value="3.1415926535897931" />

  <xacro:property name="base_dimensions" value=".9 .7 .3" />
  <xacro:property name="wheel_radius" value="${6*.0254}" />
  <xacro:property name="wheel_width" value="${4*.0254}" />

  <xacro:macro name="wheel_macro" params="index origin"> <!-- include boolean if left or right wheel-->
    <joint name="wheel_${index}_joint" type="continuous">
      <origin xyz="${origin}" rpy="0 0 0" />
      <parent link="base_link"/>
      <child link="wheel_${index}" />
      <axis xyz="0 1 0"/>
    </joint>

    <link name="wheel_${index}">
    <visual>
      <origin xyz="0 0 0" rpy="${PI/2} 0 0" />
      <geometry>
        <cylinder radius="${wheel_radius}" length="${wheel_width}"/>
      </geometry>
    </visual>
    <collision>
      <origin xyz="0 0 0" rpy="${PI/2} 0 0"/> <!--might have to rotate if wheel is flipped-->
      <geometry>
        <cylinder radius="${wheel_radius}" length="${wheel_width}"/>
      </geometry>
    </collision>
    <inertial>
      <origin xyz="0.0 0.0 0.0" rpy="0 0 0"/>
      <mass value="0.3844"/>
      <!-- Inertia based on cylinder - get from CAD -->
      <inertia
        ixx="0.000324824" ixy="0" ixz="0"
        iyy="0.000480000" iyz="0"
        izz="0.000324824"/>
    </inertial>
  </link>
  </xacro:macro>
  
  <link name="base_footprint"></link>

  <joint name="base_link_joint" type="fixed">
    <origin xyz="0 0 0.05" rpy="0 0 0" />
    <parent link="base_footprint"/>
    <child link="base_link" />
  </joint>

  <link name="base_link">
    <visual>
      <origin xyz="0 0 .2" rpy="0 0 0" />
      <geometry>
        <box size="${base_dimensions}"/>
      </geometry>
    </visual>
    <collision>
      <origin xyz="0 0 0"/>
      <geometry>
        <box size="${base_dimensions}"/>
      </geometry>
    </collision>
    <inertial>
      <!-- Fill in w/ CAD values -->
      <origin xyz="-0.01103 0 0.002" rpy="0 0 0"/>
      <mass value="2.844"/>
      <inertia
        ixx="0.018819942" ixy="0" ixz="-0.000101519"
        iyy="0.057333716" iyz="0"
        izz="0.074201740"/>
    </inertial>
  </link>

  <!-- attach wheels -->
  <xacro:wheel_macro index="0" origin=".4 .4 0"/>
  <xacro:wheel_macro index="1" origin=".4 -.4 0"/>
  <xacro:wheel_macro index="2" origin="-.4 -.4 0"/>
  <xacro:wheel_macro index="3" origin="-.4 .4 0"/>

  <!-- attach arm -->
  <xacro:include filename="$(find kortex_description)/arms/gen3/7dof/urdf/gen3_macro.xacro"/>

  <xacro:load_arm dof="7" vision="false" prefix="jaco_">
    <origin xyz="0 0 0" rpy="0 0 0"/>
  </xacro:load_arm>

  <joint name="arm_to_base_joint" type="fixed">
    <origin xyz="0 0 .35" rpy="0 0 0" />
    <parent link="base_link"/>
    <child link="jaco_base_link" />
  </joint>

  <gazebo>
    <plugin name="gazebo_ros_control" filename="libgazebo_ros_control.so">
      <robotNamespace>/</robotNamespace> 
    </plugin> 
  </gazebo> 

  </robot>
